\begin{lstlisting}[language=Python]
	
	Epoch 1/10
	8/8 - 6s - loss: 0.0000e+00 - accuracy: 0.8319 - binary_accuracy: 0.8319 - true_positives_2: 198.0000 - true_negatives_2: 0.0000e+00 - false_positives_2: 40.0000 - false_negatives_2: 0.0000e+00 - precision_at_recall_2: 0.8319 - val_loss: 0.0000e+00 - val_accuracy: 0.9054 - val_binary_accuracy: 0.9054 - val_true_positives_2: 67.0000 - val_true_negatives_2: 0.0000e+00 - val_false_positives_2: 7.0000 - val_false_negatives_2: 0.0000e+00 - val_precision_at_recall_2: 0.9054 - 6s/epoch - 777ms/step
	Epoch 2/10
	8/8 - 2s - loss: 0.0000e+00 - accuracy: 0.8319 - binary_accuracy: 0.8319 - true_positives_2: 198.0000 - true_negatives_2: 0.0000e+00 - false_positives_2: 40.0000 - false_negatives_2: 0.0000e+00 - precision_at_recall_2: 0.8319 - val_loss: 0.0000e+00 - val_accuracy: 0.9054 - val_binary_accuracy: 0.9054 - val_true_positives_2: 67.0000 - val_true_negatives_2: 0.0000e+00 - val_false_positives_2: 7.0000 - val_false_negatives_2: 0.0000e+00 - val_precision_at_recall_2: 0.9054 - 2s/epoch - 230ms/step
	Epoch 3/10
	8/8 - 2s - loss: 0.0000e+00 - accuracy: 0.8319 - binary_accuracy: 0.8319 - true_positives_2: 198.0000 - true_negatives_2: 0.0000e+00 - false_positives_2: 40.0000 - false_negatives_2: 0.0000e+00 - precision_at_recall_2: 0.8319 - val_loss: 0.0000e+00 - val_accuracy: 0.9054 - val_binary_accuracy: 0.9054 - val_true_positives_2: 67.0000 - val_true_negatives_2: 0.0000e+00 - val_false_positives_2: 7.0000 - val_false_negatives_2: 0.0000e+00 - val_precision_at_recall_2: 0.9054 - 2s/epoch - 226ms/step
	Epoch 4/10
	8/8 - 2s - loss: 0.0000e+00 - accuracy: 0.8319 - binary_accuracy: 0.8319 - true_positives_2: 198.0000 - true_negatives_2: 0.0000e+00 - false_positives_2: 40.0000 - false_negatives_2: 0.0000e+00 - precision_at_recall_2: 0.8319 - val_loss: 0.0000e+00 - val_accuracy: 0.9054 - val_binary_accuracy: 0.9054 - val_true_positives_2: 67.0000 - val_true_negatives_2: 0.0000e+00 - val_false_positives_2: 7.0000 - val_false_negatives_2: 0.0000e+00 - val_precision_at_recall_2: 0.9054 - 2s/epoch - 231ms/step
	Epoch 5/10
	8/8 - 2s - loss: 0.0000e+00 - accuracy: 0.8319 - binary_accuracy: 0.8319 - true_positives_2: 198.0000 - true_negatives_2: 0.0000e+00 - false_positives_2: 40.0000 - false_negatives_2: 0.0000e+00 - precision_at_recall_2: 0.8319 - val_loss: 0.0000e+00 - val_accuracy: 0.9054 - val_binary_accuracy: 0.9054 - val_true_positives_2: 67.0000 - val_true_negatives_2: 0.0000e+00 - val_false_positives_2: 7.0000 - val_false_negatives_2: 0.0000e+00 - val_precision_at_recall_2: 0.9054 - 2s/epoch - 228ms/step
	Epoch 6/10
	8/8 - 2s - loss: 0.0000e+00 - accuracy: 0.8319 - binary_accuracy: 0.8319 - true_positives_2: 198.0000 - true_negatives_2: 0.0000e+00 - false_positives_2: 40.0000 - false_negatives_2: 0.0000e+00 - precision_at_recall_2: 0.8319 - val_loss: 0.0000e+00 - val_accuracy: 0.9054 - val_binary_accuracy: 0.9054 - val_true_positives_2: 67.0000 - val_true_negatives_2: 0.0000e+00 - val_false_positives_2: 7.0000 - val_false_negatives_2: 0.0000e+00 - val_precision_at_recall_2: 0.9054 - 2s/epoch - 227ms/step
	Epoch 7/10
	---------------------------------------------------------------------------
	InvalidArgumentError                      Traceback (most recent call last)
	~\AppData\Local\Temp/ipykernel_4220/1411090259.py in <module>
	23 model.add(Dense(units=1, activation="softmax"))
	24 model.compile(optimizer=Adam(learning_rate=1e-3), loss=keras.losses.categorical_crossentropy, metrics=[Accuracy(), BinaryAccuracy(), TruePositives(), TrueNegatives(), FalsePositives(), FalseNegatives(), PrecisionAtRecall(0.9)])
	---> 25 res = model.fit(x=TRAIN_ARRAY, y=TRAIN_LABELS_ARRAY, epochs=10, verbose=2, validation_data = (VALIDATION_ARRAY, VALIDATION_LABELS_ARRAY) )
	
	D:\Anaconda\lib\site-packages\keras\utils\traceback_utils.py in error_handler(*args, **kwargs)
	65     except Exception as e:  # pylint: disable=broad-except
	66       filtered_tb = _process_traceback_frames(e.__traceback__)
	---> 67       raise e.with_traceback(filtered_tb) from None
	68     finally:
	69       del filtered_tb
	
	D:\Anaconda\lib\site-packages\tensorflow\python\eager\execute.py in quick_execute(op_name, num_outputs, inputs, attrs, ctx, name)
	52   try:
	53     ctx.ensure_initialized()
	---> 54     tensors = pywrap_tfe.TFE_Py_Execute(ctx._handle, device_name, op_name,
	55                                         inputs, attrs, num_outputs)
	56   except core._NotOkStatusException as e:
	
	InvalidArgumentError: Graph execution error:
	
	Detected at node 'assert_greater_equal/Assert/AssertGuard/Assert' defined at (most recent call last):
	File "D:\Anaconda\lib\runpy.py", line 197, in _run_module_as_main
	return _run_code(code, main_globals, None,
	File "D:\Anaconda\lib\runpy.py", line 87, in _run_code
	exec(code, run_globals)
	File "D:\Anaconda\lib\site-packages\ipykernel_launcher.py", line 16, in <module>
	app.launch_new_instance()
	File "D:\Anaconda\lib\site-packages\traitlets\config\application.py", line 846, in launch_instance
	app.start()
	File "D:\Anaconda\lib\site-packages\ipykernel\kernelapp.py", line 677, in start
	self.io_loop.start()
	File "D:\Anaconda\lib\site-packages\tornado\platform\asyncio.py", line 199, in start
	self.asyncio_loop.run_forever()
	File "D:\Anaconda\lib\asyncio\base_events.py", line 596, in run_forever
	self._run_once()
	File "D:\Anaconda\lib\asyncio\base_events.py", line 1890, in _run_once
	handle._run()
	File "D:\Anaconda\lib\asyncio\events.py", line 80, in _run
	self._context.run(self._callback, *self._args)
	File "D:\Anaconda\lib\site-packages\ipykernel\kernelbase.py", line 457, in dispatch_queue
	await self.process_one()
	File "D:\Anaconda\lib\site-packages\ipykernel\kernelbase.py", line 446, in process_one
	await dispatch(*args)
	File "D:\Anaconda\lib\site-packages\ipykernel\kernelbase.py", line 353, in dispatch_shell
	await result
	File "D:\Anaconda\lib\site-packages\ipykernel\kernelbase.py", line 648, in execute_request
	reply_content = await reply_content
	File "D:\Anaconda\lib\site-packages\ipykernel\ipkernel.py", line 353, in do_execute
	res = shell.run_cell(code, store_history=store_history, silent=silent)
	File "D:\Anaconda\lib\site-packages\ipykernel\zmqshell.py", line 533, in run_cell
	return super(ZMQInteractiveShell, self).run_cell(*args, **kwargs)
	File "D:\Anaconda\lib\site-packages\IPython\core\interactiveshell.py", line 2901, in run_cell
	result = self._run_cell(
	File "D:\Anaconda\lib\site-packages\IPython\core\interactiveshell.py", line 2947, in _run_cell
	return runner(coro)
	File "D:\Anaconda\lib\site-packages\IPython\core\async_helpers.py", line 68, in _pseudo_sync_runner
	coro.send(None)
	File "D:\Anaconda\lib\site-packages\IPython\core\interactiveshell.py", line 3172, in run_cell_async
	has_raised = await self.run_ast_nodes(code_ast.body, cell_name,
	File "D:\Anaconda\lib\site-packages\IPython\core\interactiveshell.py", line 3364, in run_ast_nodes
	if (await self.run_code(code, result,  async_=asy)):
	File "D:\Anaconda\lib\site-packages\IPython\core\interactiveshell.py", line 3444, in run_code
	exec(code_obj, self.user_global_ns, self.user_ns)
	File "C:\Users\estud\AppData\Local\Temp/ipykernel_4220/1411090259.py", line 25, in <module>
	res = model.fit(x=TRAIN_ARRAY, y=TRAIN_LABELS_ARRAY, epochs=10, verbose=2, validation_data = (VALIDATION_ARRAY, VALIDATION_LABELS_ARRAY) )
	File "D:\Anaconda\lib\site-packages\keras\utils\traceback_utils.py", line 64, in error_handler
	return fn(*args, **kwargs)
	File "D:\Anaconda\lib\site-packages\keras\engine\training.py", line 1384, in fit
	tmp_logs = self.train_function(iterator)
	File "D:\Anaconda\lib\site-packages\keras\engine\training.py", line 1021, in train_function
	return step_function(self, iterator)
	File "D:\Anaconda\lib\site-packages\keras\engine\training.py", line 1010, in step_function
	outputs = model.distribute_strategy.run(run_step, args=(data,))
	File "D:\Anaconda\lib\site-packages\keras\engine\training.py", line 1000, in run_step
	outputs = model.train_step(data)
	File "D:\Anaconda\lib\site-packages\keras\engine\training.py", line 864, in train_step
	return self.compute_metrics(x, y, y_pred, sample_weight)
	File "D:\Anaconda\lib\site-packages\keras\engine\training.py", line 957, in compute_metrics
	self.compiled_metrics.update_state(y, y_pred, sample_weight)
	File "D:\Anaconda\lib\site-packages\keras\engine\compile_utils.py", line 459, in update_state
	metric_obj.update_state(y_t, y_p, sample_weight=mask)
	File "D:\Anaconda\lib\site-packages\keras\utils\metrics_utils.py", line 70, in decorated
	update_op = update_state_fn(*args, **kwargs)
	File "D:\Anaconda\lib\site-packages\keras\metrics.py", line 178, in update_state_fn
	return ag_update_state(*args, **kwargs)
	File "D:\Anaconda\lib\site-packages\keras\metrics.py", line 1073, in update_state
	return metrics_utils.update_confusion_matrix_variables(
	File "D:\Anaconda\lib\site-packages\keras\utils\metrics_utils.py", line 602, in update_confusion_matrix_variables
	tf.compat.v1.assert_greater_equal(
	Node: 'assert_greater_equal/Assert/AssertGuard/Assert'
	assertion failed: [predictions must be >= 0] [Condition x >= y did not hold element-wise:] [x (sequential_11/dense_2/Softmax:0) = ] [[-nan][-nan][-nan]...] [y (Cast_11/x:0) = ] [0]
	[[{{node assert_greater_equal/Assert/AssertGuard/Assert}}]] [Op:__inference_train_function_5592]
	
\end{lstlisting}